Workbook

Sheet 29954-5 JUNHO 
B10: Anexo III da IN nº 47/2025
B12: Grade de Conciliação Bancária
B13: Referência: 06/2026
B15: CONTA CONTÁBIL: | C15: BANCO: | D15: AGÊNCIA: | E15: CONTA BANCÁRIA: | F15: TÍTULO DA CONTA: | G15: TIPO:
B16: 111111901 | C16: 1 | D16: 8-6 | E16: 29954-5 | F16: FUNDO ESTADUAL DO TRABALHO - FET | G16: (x) CONTA CORRENTE | H16: ( ) INVESTIMENTOS E APLICAÇÕES FINANCEIRAS
B17: ITEM | C17: HISTORICO | F17: DEBITO | G17: CREDITO | H17: DIFERENÇA
B18: 0 | C18: SALDO DO EXTRATO BANCÁRIO EM 30/06/2026 | F18: 0 | G18: 0
B19: 1 | C19: DEBITOS NÃO CONSTANTE NO EXTRATO | F19: 0
B20: 2 | C20: DEPÓSITOS CONSTANTES NO EXTRATO E NÃO CONTABILIZADOS | F20: 0
B21: 3 | C21: DEPÓSITOS NÃO CONSTANTES NO EXTRATO | G21: 0
B22: 4 | C22: DÉBITOS NO EXTRATO E NÃO CONTABILIZADOS | G22: 0
B23: 5.1 | C23: SALDO CONSTANTE NOS NOSSOS REGISTROS : SIAFE (Fonte Completa: 0008.0000000299545.1.7.14.9.200000.AP0000104.F) | F23: 0
B24: 5.2 | C24: SALDO CONSTANTE NOS NOSSOS REGISTROS : SIAFE (Fonte Completa:) | F24: 0
B25: 5.3 | C25: SALDO CONSTANTE NOS NOSSOS REGISTROS : SIAFE (Fonte Completa:) | F25: 0
B26: 5.4 | C26: SALDO CONSTANTE NOS NOSSOS REGISTROS : SIAFE (Fonte Completa:) | F26: 0
B27: 6 | C27: TOTAL | F27: =SUM(F18:F26) -> 0 | G27: =SUM(G18:G26) -> 0 | H27: =F27-G27 -> 0
B29: RELAÇÃO DE PENDÊNCIAS
B30: 1 - DÉBITOS NÃO CONSTANTES NO EXTRATO
B31: DATA | C31: DOCUCMENTO | D31: Nº | E31: JUSTIFICATIVA | F31: VALOR | G31: DATA DO AJUSTE | H31: REGULARIZAÇÃO
B35: TOTAL | F35: 0
B36: 2 - DEPÓSITOS NO EXTRATO E NÃO CONTABILIZADOS
B37: DATA | C37: DOCUCMENTO | D37: Nº | E37: JUSTIFICATIVA | F37: VALOR | G37: DATA DO AJUSTE | H37: REGULARIZAÇÃO
B41: TOTAL | F41: 0
B42: 3 - DEPÓSITOS NÃO CONSTANTES NO EXTRATO
B43: DATA | C43: DOCUCMENTO | D43: Nº | E43: JUSTIFICATIVA | F43: VALOR | G43: DATA DO AJUSTE | H43: REGULARIZAÇÃO
B47: TOTAL | F47: 0
B48: 4 - DÉBITOS NO EXTRATO E NÃO CONTABILIZADOS
B49: DATA | C49: DOCUCMENTO | D49: Nº | E49: JUSTIFICATIVA | F49: VALOR | G49: DATA DO AJUSTE | H49: REGULARIZAÇÃO
B53: TOTAL | F53: 0
B63: Anexo III da IN nº 47/2025
B65: Grade de Conciliação Bancária
B66: =B13 -> Referência: 06/2026
B68: CONTA CONTÁBIL: | C68: BANCO: | D68: AGÊNCIA: | E68: CONTA BANCÁRIA: | F68: TÍTULO DA CONTA: | G68: TIPO:
B69: 111111901/AP0000104 | C69: 1 | D69: 8-6 | E69: 29954-5 | F69: FUNDO ESTADUAL DO TRABALHO - FET | G69: () CONTA CORRENTE | H69: (x) INVESTIMENTOS E APLICAÇÕES FINANCEIRAS
B70: ITEM | C70: HISTORICO | F70: DEBITO | G70: CREDITO | H70: DIFERENÇA
B71: 0 | C71: SALDO DO EXTRATO BANCÁRIO EM 30/06/2026 | F71: 0 | G71: 1684193
B72: 1 | C72: DEBITOS NÃO CONSTANTE NO EXTRATO | F72: 0
B73: 2 | C73: DEPÓSITOS CONSTANTES NO EXTRATO E NÃO CONTABILIZADOS | F73: 0
B74: 3 | C74: DEPÓSITOS NÃO CONSTANTES NO EXTRATO | G74: 0
B75: 4 | C75: DÉBITOS NO EXTRATO E NÃO CONTABILIZADOS | G75: 0
...

Sheet 29955-3 JUNHO 
B10: Anexo III da IN nº 47/2025
B11: Grade de Conciliação Bancária
B12: ='29954-5 JUNHO '!B13:H13 -> Referência: 06/2026
B14: CONTA CONTÁBIL: | C14: BANCO: | D14: AGÊNCIA: | E14: CONTA BANCÁRIA: | F14: TÍTULO DA CONTA: | G14: TIPO:
B15: 111111901 | C15: 1 | D15: 8-6 | E15: 29955-3 | F15: FUNDO ESTADUAL DO TRABALHO - FET | G15: (x) CONTA CORRENTE | H15: ( ) INVESTIMENTOS E APLICAÇÕES FINANCEIRAS
B16: ITEM | C16: HISTORICO | F16: DEBITO | G16: CREDITO | H16: DIFERENÇA
B17: 0 | C17: ='29954-5 JUNHO '!C18:E18 -> SALDO DO EXTRATO BANCÁRIO EM 30/06/2026 | F17: 0 | G17: 0
B18: 1 | C18: DEBITOS NÃO CONSTANTE NO EXTRATO | F18: 0
B19: 2 | C19: DEPÓSITOS CONSTANTES NO EXTRATO E NÃO CONTABILIZADOS | F19: 0
B20: 3 | C20: DEPÓSITOS NÃO CONSTANTES NO EXTRATO | G20: 0
B21: 4 | C21: DÉBITOS NO EXTRATO E NÃO CONTABILIZADOS | G21: 0
B22: 5.1 | C22: SALDO CONSTANTE NOS NOSSOS REGISTROS : SIAFE (Fonte Completa:) | F22: 0
B23: 5.2 | C23: SALDO CONSTANTE NOS NOSSOS REGISTROS : SIAFE (Fonte Completa:) | F23: 0
B24: 5.3 | C24: SALDO CONSTANTE NOS NOSSOS REGISTROS : SIAFE (Fonte Completa:) | F24: 0
B25: 5.4 | C25: SALDO CONSTANTE NOS NOSSOS REGISTROS : SIAFE (Fonte Completa:) | F25: 0
B26: 6 | C26: TOTAL | F26: 0 | G26: 0 | H26: 0
B28: RELAÇÃO DE PENDÊNCIAS
B29: 1 - DÉBITOS NÃO CONSTANTES NO EXTRATO
B30: DATA | C30: DOCUCMENTO | D30: Nº | E30: JUSTIFICATIVA | F30: VALOR | G30: DATA DO AJUSTE | H30: REGULARIZAÇÃO
B34: TOTAL | F34: 0
B35: 2 - DEPÓSITOS NO EXTRATO E NÃO CONTABILIZADOS
B36: DATA | C36: DOCUCMENTO | D36: Nº | E36: JUSTIFICATIVA | F36: VALOR | G36: DATA DO AJUSTE | H36: REGULARIZAÇÃO
B40: TOTAL | F40: 0
B41: 3 - DEPÓSITOS NÃO CONSTANTES NO EXTRATO
B42: DATA | C42: DOCUCMENTO | D42: Nº | E42: JUSTIFICATIVA | F42: VALOR | G42: DATA DO AJUSTE | H42: REGULARIZAÇÃO
B46: TOTAL | F46: 0
B47: 4 - DÉBITOS NO EXTRATO E NÃO CONTABILIZADOS
B48: DATA | C48: DOCUCMENTO | D48: Nº | E48: JUSTIFICATIVA | F48: VALOR | G48: DATA DO AJUSTE | H48: REGULARIZAÇÃO
B52: TOTAL | F52: 0
B61: Anexo III da IN nº 47/2025
B62: Grade de Conciliação Bancária
B63: =B12 -> Referência: 06/2026
B64: CONTA CONTÁBIL: | C64: BANCO: | D64: AGÊNCIA: | E64: CONTA BANCÁRIA: | F64: TÍTULO DA CONTA: | G64: TIPO:
B65: ='29954-5 JUNHO '!B69 -> 111111901/AP0000104 | C65: 1 | D65: 8-6 | E65: =E15 -> 29955-3 | F65: FUNDO ESTADUAL DO TRABALHO - FET | G65: () CONTA CORRENTE | H65: (x) INVESTIMENTOS E APLICAÇÕES FINANCEIRAS
B66: ITEM | C66: HISTORICO | F66: DEBITO | G66: CREDITO | H66: DIFERENÇA
B67: 0 | C67: =C17 -> SALDO DO EXTRATO BANCÁRIO EM 30/06/2026 | F67: 0 | G67: 245243.05
B68: 1 | C68: DEBITOS NÃO CONSTANTE NO EXTRATO | F68: 0
B69: 2 | C69: DEPÓSITOS CONSTANTES NO EXTRATO E NÃO CONTABILIZADOS | F69: 0
B70: 3 | C70: DEPÓSITOS NÃO CONSTANTES NO EXTRATO | G70: 0
B71: 4 | C71: DÉBITOS NO EXTRATO E NÃO CONTABILIZADOS | G71: 0
...

Sheet 29055-6 JUNHO
B10: Anexo III da IN nº 47/2025
B11: Grade de Conciliação Bancária
B12: ='29954-5 JUNHO '!B13:H13 -> Referência: 06/2026
B14: CONTA CONTÁBIL: | C14: BANCO: | D14: AGÊNCIA: | E14: CONTA BANCÁRIA: | F14: TÍTULO DA CONTA: | G14: TIPO:
B15: 111111901 | C15: 1 | D15: 8-6 | E15: 29055-6 | F15: FUNDO ESTADUAL DO TRABALHO - FET | G15: (x) CONTA CORRENTE | H15: ( ) INVESTIMENTOS E APLICAÇÕES FINANCEIRAS
B16: ITEM | C16: HISTORICO | F16: DEBITO | G16: CREDITO | H16: DIFERENÇA
B17: 0 | C17: ='29954-5 JUNHO '!C18:E18 -> SALDO DO EXTRATO BANCÁRIO EM 30/06/2026 | F17: 0 | G17: 0
B18: 1 | C18: DEBITOS NÃO CONSTANTE NO EXTRATO | F18: 0
B19: 2 | C19: DEPÓSITOS CONSTANTES NO EXTRATO E NÃO CONTABILIZADOS | F19: 0
B20: 3 | C20: DEPÓSITOS NÃO CONSTANTES NO EXTRATO | G20: 0
B21: 4 | C21: DÉBITOS NO EXTRATO E NÃO CONTABILIZADOS | G21: 0
B22: 5.1 | C22: SALDO CONSTANTE NOS NOSSOS REGISTROS : SIAFE (Fonte Completa:) | F22: 0
B23: 5.2 | C23: SALDO CONSTANTE NOS NOSSOS REGISTROS : SIAFE (Fonte Completa:) | F23: 0
B24: 5.3 | C24: SALDO CONSTANTE NOS NOSSOS REGISTROS : SIAFE (Fonte Completa:) | F24: 0
B25: 5.4 | C25: SALDO CONSTANTE NOS NOSSOS REGISTROS : SIAFE (Fonte Completa:) | F25: 0
B26: 6 | C26: TOTAL | F26: 0 | G26: 0 | H26: 0
B28: RELAÇÃO DE PENDÊNCIAS
B29: 1 - DÉBITOS NÃO CONSTANTES NO EXTRATO
B30: DATA | C30: DOCUCMENTO | D30: Nº | E30: JUSTIFICATIVA | F30: VALOR | G30: DATA DO AJUSTE | H30: REGULARIZAÇÃO
B34: TOTAL | F34: 0
B35: 2 - DEPÓSITOS NO EXTRATO E NÃO CONTABILIZADOS
B36: DATA | C36: DOCUCMENTO | D36: Nº | E36: JUSTIFICATIVA | F36: VALOR | G36: DATA DO AJUSTE | H36: REGULARIZAÇÃO
B40: TOTAL | F40: 0
B41: 3 - DEPÓSITOS NÃO CONSTANTES NO EXTRATO
B42: DATA | C42: DOCUCMENTO | D42: Nº | E42: JUSTIFICATIVA | F42: VALOR | G42: DATA DO AJUSTE | H42: REGULARIZAÇÃO
B46: TOTAL | F46: 0
B47: 4 - DÉBITOS NO EXTRATO E NÃO CONTABILIZADOS
B48: DATA | C48: DOCUCMENTO | D48: Nº | E48: JUSTIFICATIVA | F48: VALOR | G48: DATA DO AJUSTE | H48: REGULARIZAÇÃO
B52: TOTAL | F52: 0
B63: Anexo III da IN nº 47/2025
B64: Grade de Conciliação Bancária
B65: =B12 -> Referência: 06/2026
B66: CONTA CONTÁBIL: | C66: BANCO: | D66: AGÊNCIA: | E66: CONTA BANCÁRIA: | F66: TÍTULO DA CONTA: | G66: TIPO:
B67: ='29954-5 JUNHO '!B69 -> 111111901/AP0000104 | C67: 1 | D67: 8-6 | E67: =E15 -> 29055-6 | F67: FUNDO ESTADUAL DO TRABALHO - FET | G67: () CONTA CORRENTE | H67: (x) INVESTIMENTOS E APLICAÇÕES FINANCEIRAS
B68: ITEM | C68: HISTORICO | F68: DEBITO | G68: CREDITO | H68: DIFERENÇA
B69: 0 | C69: =C17 -> SALDO DO EXTRATO BANCÁRIO EM 30/06/2026 | F69: 0 | G69: 0
B70: 1 | C70: DEBITOS NÃO CONSTANTE NO EXTRATO | F70: 0
B71: 2 | C71: DEPÓSITOS CONSTANTES NO EXTRATO E NÃO CONTABILIZADOS | F71: 0
B72: 3 | C72: DEPÓSITOS NÃO CONSTANTES NO EXTRATO | G72: 0
B73: 4 | C73: DÉBITOS NO EXTRATO E NÃO CONTABILIZADOS | G73: 0
...

Sheet 29957-X JUNHO
B10: Anexo III da IN nº 47/2025
B11: Grade de Conciliação Bancária
B12: ='29954-5 JUNHO '!B13:H13 -> Referência: 06/2026
B14: CONTA CONTÁBIL: | C14: BANCO: | D14: AGÊNCIA: | E14: CONTA BANCÁRIA: | F14: TÍTULO DA CONTA: | G14: TIPO:
B15: 111111901 | C15: 1 | D15: 8-6 | E15: 29957-X | F15: FUNDO ESTADUAL DO TRABALHO - FET | G15: (x) CONTA CORRENTE | H15: ( ) INVESTIMENTOS E APLICAÇÕES FINANCEIRAS
B16: ITEM | C16: HISTORICO | F16: DEBITO | G16: CREDITO | H16: DIFERENÇA
B17: 0 | C17: ='29954-5 JUNHO '!C18:E18 -> SALDO DO EXTRATO BANCÁRIO EM 30/06/2026 | F17: 0 | G17: 0
B18: 1 | C18: DEBITOS NÃO CONSTANTE NO EXTRATO | F18: 0
B19: 2 | C19: DEPÓSITOS CONSTANTES NO EXTRATO E NÃO CONTABILIZADOS | F19: 0
B20: 3 | C20: DEPÓSITOS NÃO CONSTANTES NO EXTRATO | G20: 0
B21: 4 | C21: DÉBITOS NO EXTRATO E NÃO CONTABILIZADOS | G21: 0
B22: 5.1 | C22: SALDO CONSTANTE NOS NOSSOS REGISTROS : SIAFE (Fonte Completa:) | F22: 0
B23: 5.2 | C23: SALDO CONSTANTE NOS NOSSOS REGISTROS : SIAFE (Fonte Completa:) | F23: 0
B24: 5.3 | C24: SALDO CONSTANTE NOS NOSSOS REGISTROS : SIAFE (Fonte Completa:) | F24: 0
B25: 5.4 | C25: SALDO CONSTANTE NOS NOSSOS REGISTROS : SIAFE (Fonte Completa:) | F25: 0
B26: 6 | C26: TOTAL | F26: 0 | G26: 0 | H26: 0
B28: RELAÇÃO DE PENDÊNCIAS
B29: 1 - DÉBITOS NÃO CONSTANTES NO EXTRATO
B30: DATA | C30: DOCUCMENTO | D30: Nº | E30: JUSTIFICATIVA | F30: VALOR | G30: DATA DO AJUSTE | H30: REGULARIZAÇÃO
B34: TOTAL | F34: 0
B35: 2 - DEPÓSITOS NO EXTRATO E NÃO CONTABILIZADOS
B36: DATA | C36: DOCUCMENTO | D36: Nº | E36: JUSTIFICATIVA | F36: VALOR | G36: DATA DO AJUSTE | H36: REGULARIZAÇÃO
B40: TOTAL | F40: 0
B41: 3 - DEPÓSITOS NÃO CONSTANTES NO EXTRATO
B42: DATA | C42: DOCUCMENTO | D42: Nº | E42: JUSTIFICATIVA | F42: VALOR | G42: DATA DO AJUSTE | H42: REGULARIZAÇÃO
B46: TOTAL | F46: 0
B47: 4 - DÉBITOS NO EXTRATO E NÃO CONTABILIZADOS
B48: DATA | C48: DOCUCMENTO | D48: Nº | E48: JUSTIFICATIVA | F48: VALOR | G48: DATA DO AJUSTE | H48: REGULARIZAÇÃO
B52: TOTAL | F52: 0
B64: Anexo III da IN nº 47/2025
B65: Grade de Conciliação Bancária
B66: =B12 -> Referência: 06/2026
B67: CONTA CONTÁBIL: | C67: BANCO: | D67: AGÊNCIA: | E67: CONTA BANCÁRIA: | F67: TÍTULO DA CONTA: | G67: TIPO:
B68: ='29954-5 JUNHO '!B69 -> 111111901/AP0000104 | C68: 1 | D68: 8-6 | E68: =E15 -> 29957-X | F68: FUNDO ESTADUAL DO TRABALHO - FET | G68: () CONTA CORRENTE | H68: (x) INVESTIMENTOS E APLICAÇÕES FINANCEIRAS
B69: ITEM | C69: HISTORICO | F69: DEBITO | G69: CREDITO | H69: DIFERENÇA
B70: 0 | C70: =C17 -> SALDO DO EXTRATO BANCÁRIO EM 30/06/2026 | F70: 0 | G70: 97717.77
B71: 1 | C71: DEBITOS NÃO CONSTANTE NO EXTRATO | F71: 0
B72: 2 | C72: DEPÓSITOS CONSTANTES NO EXTRATO E NÃO CONTABILIZADOS | F72: 0
B73: 3 | C73: DEPÓSITOS NÃO CONSTANTES NO EXTRATO | G73: 0
B74: 4 | C74: DÉBITOS NO EXTRATO E NÃO CONTABILIZADOS | G74: 0
...

Sheet 29851-4 JUNHO
B10: Anexo III da IN nº 47/2025
B11: Grade de Conciliação Bancária
B12: ='29954-5 JUNHO '!B13:H13 -> Referência: 06/2026
B14: CONTA CONTÁBIL: | C14: BANCO: | D14: AGÊNCIA: | E14: CONTA BANCÁRIA: | F14: TÍTULO DA CONTA: | G14: TIPO:
B15: 111111901 | C15: 1 | D15: 8-6 | E15: 29851-4 | F15: FUNDO ESTADUAL DO TRABALHO - FET | G15: (x) CONTA CORRENTE | H15: ( ) INVESTIMENTOS E APLICAÇÕES FINANCEIRAS
B16: ITEM | C16: HISTORICO | F16: DEBITO | G16: CREDITO | H16: DIFERENÇA
B17: 0 | C17: ='29954-5 JUNHO '!C18:E18 -> SALDO DO EXTRATO BANCÁRIO EM 30/06/2026 | F17: 0 | G17: 0
B18: 1 | C18: DEBITOS NÃO CONSTANTE NO EXTRATO | F18: 0
B19: 2 | C19: DEPÓSITOS CONSTANTES NO EXTRATO E NÃO CONTABILIZADOS | F19: 0
B20: 3 | C20: DEPÓSITOS NÃO CONSTANTES NO EXTRATO | G20: 0
B21: 4 | C21: DÉBITOS NO EXTRATO E NÃO CONTABILIZADOS | G21: 0
B22: 5.1 | C22: SALDO CONSTANTE NOS NOSSOS REGISTROS : SIAFE (Fonte Completa:) | F22: 0
B23: 5.2 | C23: SALDO CONSTANTE NOS NOSSOS REGISTROS : SIAFE (Fonte Completa:) | F23: 0
B24: 5.3 | C24: SALDO CONSTANTE NOS NOSSOS REGISTROS : SIAFE (Fonte Completa:) | F24: 0
B25: 5.4 | C25: SALDO CONSTANTE NOS NOSSOS REGISTROS : SIAFE (Fonte Completa:) | F25: 0
B26: 6 | C26: TOTAL | F26: 0 | G26: 0 | H26: 0
B28: RELAÇÃO DE PENDÊNCIAS
B29: 1 - DÉBITOS NÃO CONSTANTES NO EXTRATO
B30: DATA | C30: DOCUCMENTO | D30: Nº | E30: JUSTIFICATIVA | F30: VALOR | G30: DATA DO AJUSTE | H30: REGULARIZAÇÃO
B34: TOTAL | F34: 0
B35: 2 - DEPÓSITOS NO EXTRATO E NÃO CONTABILIZADOS
B36: DATA | C36: DOCUCMENTO | D36: Nº | E36: JUSTIFICATIVA | F36: VALOR | G36: DATA DO AJUSTE | H36: REGULARIZAÇÃO
B40: TOTAL | F40: 0
B41: 3 - DEPÓSITOS NÃO CONSTANTES NO EXTRATO
B42: DATA | C42: DOCUCMENTO | D42: Nº | E42: JUSTIFICATIVA | F42: VALOR | G42: DATA DO AJUSTE | H42: REGULARIZAÇÃO
B46: TOTAL | F46: 0
B47: 4 - DÉBITOS NO EXTRATO E NÃO CONTABILIZADOS
B48: DATA | C48: DOCUCMENTO | D48: Nº | E48: JUSTIFICATIVA | F48: VALOR | G48: DATA DO AJUSTE | H48: REGULARIZAÇÃO
B52: TOTAL | F52: 0
B64: Anexo III da IN nº 47/2025
B65: Grade de Conciliação Bancária
B66: =B12 -> Referência: 06/2026
B67: CONTA CONTÁBIL: | C67: BANCO: | D67: AGÊNCIA: | E67: CONTA BANCÁRIA: | F67: TÍTULO DA CONTA: | G67: TIPO:
B68: ='29954-5 JUNHO '!B69 -> 111111901/AP0000104 | C68: 1 | D68: 8-6 | E68: =E15 -> 29851-4 | F68: FUNDO ESTADUAL DO TRABALHO - FET | G68: () CONTA CORRENTE | H68: (x) INVESTIMENTOS E APLICAÇÕES FINANCEIRAS
B69: ITEM | C69: HISTORICO | F69: DEBITO | G69: CREDITO | H69: DIFERENÇA
B70: 0 | C70: =C17 -> SALDO DO EXTRATO BANCÁRIO EM 30/06/2026 | F70: 0 | G70: 0
B71: 1 | C71: DEBITOS NÃO CONSTANTE NO EXTRATO | F71: 0
B72: 2 | C72: DEPÓSITOS CONSTANTES NO EXTRATO E NÃO CONTABILIZADOS | F72: 0
B73: 3 | C73: DEPÓSITOS NÃO CONSTANTES NO EXTRATO | G73: 0
B74: 4 | C74: DÉBITOS NO EXTRATO E NÃO CONTABILIZADOS | G74: 0
...

Sheet 29958-8 JUNHO 
B10: Anexo III da IN nº 47/2025
B12: Grade de Conciliação Bancária
B13: ='29954-5 JUNHO '!B13:H13 -> Referência: 06/2026
B15: CONTA CONTÁBIL: | C15: BANCO: | D15: AGÊNCIA: | E15: CONTA BANCÁRIA: | F15: TÍTULO DA CONTA: | G15: TIPO:
B16: 111111901 | C16: 1 | D16: 8-6 | E16: 29958-8 | F16: FUNDO ESTADUAL DO TRABALHO - FET | G16: (x) CONTA CORRENTE | H16: ( ) INVESTIMENTOS E APLICAÇÕES FINANCEIRAS
B17: ITEM | C17: HISTORICO | F17: DEBITO | G17: CREDITO | H17: DIFERENÇA
B18: 0 | C18: ='29954-5 JUNHO '!C18:E18 -> SALDO DO EXTRATO BANCÁRIO EM 30/06/2026 | F18: 0 | G18: 0
B19: 1 | C19: DEBITOS NÃO CONSTANTE NO EXTRATO | F19: 0
B20: 2 | C20: DEPÓSITOS CONSTANTES NO EXTRATO E NÃO CONTABILIZADOS | F20: 0
B21: 3 | C21: DEPÓSITOS NÃO CONSTANTES NO EXTRATO | G21: 0
B22: 4 | C22: DÉBITOS NO EXTRATO E NÃO CONTABILIZADOS | G22: 0
B23: 5.1 | C23: SALDO CONSTANTE NOS NOSSOS REGISTROS : SIAFE (Fonte Completa:) | F23: 0
B24: 5.2 | C24: SALDO CONSTANTE NOS NOSSOS REGISTROS : SIAFE (Fonte Completa:) | F24: 0
B25: 5.3 | C25: SALDO CONSTANTE NOS NOSSOS REGISTROS : SIAFE (Fonte Completa:) | F25: 0
B26: 5.4 | C26: SALDO CONSTANTE NOS NOSSOS REGISTROS : SIAFE (Fonte Completa:) | F26: 0
B27: 6 | C27: TOTAL | F27: 0 | G27: 0 | H27: 0
B29: RELAÇÃO DE PENDÊNCIAS
B30: 1 - DÉBITOS NÃO CONSTANTES NO EXTRATO
B31: DATA | C31: DOCUCMENTO | D31: Nº | E31: JUSTIFICATIVA | F31: VALOR | G31: DATA DO AJUSTE | H31: REGULARIZAÇÃO
B35: TOTAL | F35: 0
B36: 2 - DEPÓSITOS NO EXTRATO E NÃO CONTABILIZADOS
B37: DATA | C37: DOCUCMENTO | D37: Nº | E37: JUSTIFICATIVA | F37: VALOR | G37: DATA DO AJUSTE | H37: REGULARIZAÇÃO
B41: TOTAL | F41: 0
B42: 3 - DEPÓSITOS NÃO CONSTANTES NO EXTRATO
B43: DATA | C43: DOCUCMENTO | D43: Nº | E43: JUSTIFICATIVA | F43: VALOR | G43: DATA DO AJUSTE | H43: REGULARIZAÇÃO
B47: TOTAL | F47: 0
B48: 4 - DÉBITOS NO EXTRATO E NÃO CONTABILIZADOS
B49: DATA | C49: DOCUCMENTO | D49: Nº | E49: JUSTIFICATIVA | F49: VALOR | G49: DATA DO AJUSTE | H49: REGULARIZAÇÃO
B53: TOTAL | F53: 0
B63: Anexo III da IN nº 47/2025
B64: Grade de Conciliação Bancária
B65: =B13 -> Referência: 06/2026
B66: CONTA CONTÁBIL: | C66: BANCO: | D66: AGÊNCIA: | E66: CONTA BANCÁRIA: | F66: TÍTULO DA CONTA: | G66: TIPO:
B67: ='29954-5 JUNHO '!B69 -> 111111901/AP0000104 | C67: 1 | D67: 8-6 | E67: =E16 -> 29958-8 | F67: FUNDO ESTADUAL DO TRABALHO - FET | G67: () CONTA CORRENTE | H67: (x) INVESTIMENTOS E APLICAÇÕES FINANCEIRAS
B68: ITEM | C68: HISTORICO | F68: DEBITO | G68: CREDITO | H68: DIFERENÇA
B69: 0 | C69: =C18 -> SALDO DO EXTRATO BANCÁRIO EM 30/06/2026 | F69: 0 | G69: 6933.74
B70: 1 | C70: DEBITOS NÃO CONSTANTE NO EXTRATO | F70: 0
B71: 2 | C71: DEPÓSITOS CONSTANTES NO EXTRATO E NÃO CONTABILIZADOS | F71: 0
B72: 3 | C72: DEPÓSITOS NÃO CONSTANTES NO EXTRATO | G72: 0
B73: 4 | C73: DÉBITOS NO EXTRATO E NÃO CONTABILIZADOS | G73: 0
...

Sheet 29081-5 JUNHO 
B10: Anexo III da IN nº 47/2025
B12: Grade de Conciliação Bancária
B13: ='29954-5 JUNHO '!B13:H13 -> Referência: 06/2026
B15: CONTA CONTÁBIL: | C15: BANCO: | D15: AGÊNCIA: | E15: CONTA BANCÁRIA: | F15: TÍTULO DA CONTA: | G15: TIPO:
B16: 111111901 | C16: 1 | D16: 8-6 | E16: 29081-5 | F16: FUNDO ESTADUAL DO TRABALHO - FET | G16: (x) CONTA CORRENTE | H16: ( ) INVESTIMENTOS E APLICAÇÕES FINANCEIRAS
B17: ITEM | C17: HISTORICO | F17: DEBITO | G17: CREDITO | H17: DIFERENÇA
B18: 0 | C18: ='29954-5 JUNHO '!C18:E18 -> SALDO DO EXTRATO BANCÁRIO EM 30/06/2026 | F18: 0 | G18: 0
B19: 1 | C19: DEBITOS NÃO CONSTANTE NO EXTRATO | F19: 0
B20: 2 | C20: DEPÓSITOS CONSTANTES NO EXTRATO E NÃO CONTABILIZADOS | F20: 0
B21: 3 | C21: DEPÓSITOS NÃO CONSTANTES NO EXTRATO | G21: 0
B22: 4 | C22: DÉBITOS NO EXTRATO E NÃO CONTABILIZADOS | G22: 0
B23: 5.1 | C23: SALDO CONSTANTE NOS NOSSOS REGISTROS : SIAFE (Fonte Completa:) | F23: 0
B24: 5.2 | C24: SALDO CONSTANTE NOS NOSSOS REGISTROS : SIAFE (Fonte Completa:) | F24: 0
B25: 5.3 | C25: SALDO CONSTANTE NOS NOSSOS REGISTROS : SIAFE (Fonte Completa:) | F25: 0
B26: 5.4 | C26: SALDO CONSTANTE NOS NOSSOS REGISTROS : SIAFE (Fonte Completa:) | F26: 0
B27: 6 | C27: TOTAL | F27: 0 | G27: 0 | H27: 0
B29: RELAÇÃO DE PENDÊNCIAS
B30: 1 - DÉBITOS NÃO CONSTANTES NO EXTRATO
B31: DATA | C31: DOCUCMENTO | D31: Nº | E31: JUSTIFICATIVA | F31: VALOR | G31: DATA DO AJUSTE | H31: REGULARIZAÇÃO
B35: TOTAL | F35: 0
B36: 2 - DEPÓSITOS NO EXTRATO E NÃO CONTABILIZADOS
B37: DATA | C37: DOCUCMENTO | D37: Nº | E37: JUSTIFICATIVA | F37: VALOR | G37: DATA DO AJUSTE | H37: REGULARIZAÇÃO
B41: TOTAL | F41: 0
B42: 3 - DEPÓSITOS NÃO CONSTANTES NO EXTRATO
B43: DATA | C43: DOCUCMENTO | D43: Nº | E43: JUSTIFICATIVA | F43: VALOR | G43: DATA DO AJUSTE | H43: REGULARIZAÇÃO
B47: TOTAL | F47: 0
B48: 4 - DÉBITOS NO EXTRATO E NÃO CONTABILIZADOS
B49: DATA | C49: DOCUCMENTO | D49: Nº | E49: JUSTIFICATIVA | F49: VALOR | G49: DATA DO AJUSTE | H49: REGULARIZAÇÃO
B53: TOTAL | F53: 0
B65: Anexo III da IN nº 47/2025
B66: Grade de Conciliação Bancária
B67: =B13 -> Referência: 06/2026
B68: CONTA CONTÁBIL: | C68: BANCO: | D68: AGÊNCIA: | E68: CONTA BANCÁRIA: | F68: TÍTULO DA CONTA: | G68: TIPO:
B69: ='29954-5 JUNHO '!B69 -> 111111901/AP0000104 | C69: 1 | D69: 8-6 | E69: =E16 -> 29081-5 | F69: FUNDO ESTADUAL DO TRABALHO - FET | G69: () CONTA CORRENTE | H69: (x) INVESTIMENTOS E APLICAÇÕES FINANCEIRAS
B70: ITEM | C70: HISTORICO | F70: DEBITO | G70: CREDITO | H70: DIFERENÇA
B71: 0 | C71: =C18 -> SALDO DO EXTRATO BANCÁRIO EM 30/06/2026 | F71: 0 | G71: 0
B72: 1 | C72: DEBITOS NÃO CONSTANTE NO EXTRATO | F72: 0
B73: 2 | C73: DEPÓSITOS CONSTANTES NO EXTRATO E NÃO CONTABILIZADOS | F73: 0
B74: 3 | C74: DEPÓSITOS NÃO CONSTANTES NO EXTRATO | G74: 0
B75: 4 | C75: DÉBITOS NO EXTRATO E NÃO CONTABILIZADOS | G75: 0
...

Sheet 29956-1 JUNHO
B10: Anexo III da IN nº 47/2025
B11: Grade de Conciliação Bancária
B12: ='29954-5 JUNHO '!B13:H13 -> Referência: 06/2026
B14: CONTA CONTÁBIL: | C14: BANCO: | D14: AGÊNCIA: | E14: CONTA BANCÁRIA: | F14: TÍTULO DA CONTA: | G14: TIPO:
B15: 111111901 | C15: 1 | D15: 8-6 | E15: 29956-1 | F15: FUNDO ESTADUAL DO TRABALHO - FET | G15: (x) CONTA CORRENTE | H15: ( ) INVESTIMENTOS E APLICAÇÕES FINANCEIRAS
B16: ITEM | C16: HISTORICO | F16: DEBITO | G16: CREDITO | H16: DIFERENÇA
B17: 0 | C17: ='29954-5 JUNHO '!C18:E18 -> SALDO DO EXTRATO BANCÁRIO EM 30/06/2026 | F17: 0 | G17: 0
B18: 1 | C18: DEBITOS NÃO CONSTANTE NO EXTRATO | F18: 0
B19: 2 | C19: DEPÓSITOS CONSTANTES NO EXTRATO E NÃO CONTABILIZADOS | F19: 0
B20: 3 | C20: DEPÓSITOS NÃO CONSTANTES NO EXTRATO | G20: 0
B21: 4 | C21: DÉBITOS NO EXTRATO E NÃO CONTABILIZADOS | G21: 0
B22: 5.1 | C22: SALDO CONSTANTE NOS NOSSOS REGISTROS : SIAFE (Fonte Completa:) | F22: 0
B23: 5.2 | C23: SALDO CONSTANTE NOS NOSSOS REGISTROS : SIAFE (Fonte Completa:) | F23: 0
B24: 5.3 | C24: SALDO CONSTANTE NOS NOSSOS REGISTROS : SIAFE (Fonte Completa:) | F24: 0
B25: 5.4 | C25: SALDO CONSTANTE NOS NOSSOS REGISTROS : SIAFE (Fonte Completa:) | F25: 0
B26: 6 | C26: TOTAL | F26: 0 | G26: 0 | H26: 0
B28: RELAÇÃO DE PENDÊNCIAS
B29: 1 - DÉBITOS NÃO CONSTANTES NO EXTRATO
B30: DATA | C30: DOCUCMENTO | D30: Nº | E30: JUSTIFICATIVA | F30: VALOR | G30: DATA DO AJUSTE | H30: REGULARIZAÇÃO
B34: TOTAL | F34: 0
B35: 2 - DEPÓSITOS NO EXTRATO E NÃO CONTABILIZADOS
B36: DATA | C36: DOCUCMENTO | D36: Nº | E36: JUSTIFICATIVA | F36: VALOR | G36: DATA DO AJUSTE | H36: REGULARIZAÇÃO
B40: TOTAL | F40: 0
B41: 3 - DEPÓSITOS NÃO CONSTANTES NO EXTRATO
B42: DATA | C42: DOCUCMENTO | D42: Nº | E42: JUSTIFICATIVA | F42: VALOR | G42: DATA DO AJUSTE | H42: REGULARIZAÇÃO
B46: TOTAL | F46: 0
B47: 4 - DÉBITOS NO EXTRATO E NÃO CONTABILIZADOS
B48: DATA | C48: DOCUCMENTO | D48: Nº | E48: JUSTIFICATIVA | F48: VALOR | G48: DATA DO AJUSTE | H48: REGULARIZAÇÃO
B52: TOTAL | F52: 0
B64: Anexo III da IN nº 47/2025
B65: Grade de Conciliação Bancária
B66: =B12 -> Referência: 06/2026
B67: CONTA CONTÁBIL: | C67: BANCO: | D67: AGÊNCIA: | E67: CONTA BANCÁRIA: | F67: TÍTULO DA CONTA: | G67: TIPO:
B68: ='29954-5 JUNHO '!B69 -> 111111901/AP0000104 | C68: 1 | D68: 8-6 | E68: =E15 -> 29956-1 | F68: FUNDO ESTADUAL DO TRABALHO - FET | G68: () CONTA CORRENTE | H68: (x) INVESTIMENTOS E APLICAÇÕES FINANCEIRAS
B69: ITEM | C69: HISTORICO | F69: DEBITO | G69: CREDITO | H69: DIFERENÇA
B70: 0 | C70: =C17 -> SALDO DO EXTRATO BANCÁRIO EM 30/06/2026 | F70: 0 | G70: 34803.68
B71: 1 | C71: DEBITOS NÃO CONSTANTE NO EXTRATO | F71: 0
B72: 2 | C72: DEPÓSITOS CONSTANTES NO EXTRATO E NÃO CONTABILIZADOS | F72: 0
B73: 3 | C73: DEPÓSITOS NÃO CONSTANTES NO EXTRATO | G73: 0
B74: 4 | C74: DÉBITOS NO EXTRATO E NÃO CONTABILIZADOS | G74: 0
...

Sheet 29054-8 JUNHO 
B10: Anexo III da IN nº 47/2025
B12: Grade de Conciliação Bancária
B13: ='29954-5 JUNHO '!B13:H13 -> Referência: 06/2026
B15: CONTA CONTÁBIL: | C15: BANCO: | D15: AGÊNCIA: | E15: CONTA BANCÁRIA: | F15: TÍTULO DA CONTA: | G15: TIPO:
B16: 111111901 | C16: 1 | D16: 8-6 | E16: 29054-8 | F16: FUNDO ESTADUAL DO TRABALHO - FET | G16: (x) CONTA CORRENTE | H16: ( ) INVESTIMENTOS E APLICAÇÕES FINANCEIRAS
B17: ITEM | C17: HISTORICO | F17: DEBITO | G17: CREDITO | H17: DIFERENÇA
B18: 0 | C18: ='29954-5 JUNHO '!C18:E18 -> SALDO DO EXTRATO BANCÁRIO EM 30/06/2026 | F18: 0 | G18: 0
B19: 1 | C19: DEBITOS NÃO CONSTANTE NO EXTRATO | F19: 0
B20: 2 | C20: DEPÓSITOS CONSTANTES NO EXTRATO E NÃO CONTABILIZADOS | F20: 0
B21: 3 | C21: DEPÓSITOS NÃO CONSTANTES NO EXTRATO | G21: 0
B22: 4 | C22: DÉBITOS NO EXTRATO E NÃO CONTABILIZADOS | G22: 0
B23: 5.1 | C23: SALDO CONSTANTE NOS NOSSOS REGISTROS : SIAFE (Fonte Completa:) | F23: 0
B24: 5.2 | C24: SALDO CONSTANTE NOS NOSSOS REGISTROS : SIAFE (Fonte Completa:) | F24: 0
B25: 5.3 | C25: SALDO CONSTANTE NOS NOSSOS REGISTROS : SIAFE (Fonte Completa:) | F25: 0
B26: 5.4 | C26: SALDO CONSTANTE NOS NOSSOS REGISTROS : SIAFE (Fonte Completa:) | F26: 0
B27: 6 | C27: TOTAL | F27: 0 | G27: 0 | H27: 0
B29: RELAÇÃO DE PENDÊNCIAS
B30: 1 - DÉBITOS NÃO CONSTANTES NO EXTRATO
B31: DATA | C31: DOCUCMENTO | D31: Nº | E31: JUSTIFICATIVA | F31: VALOR | G31: DATA DO AJUSTE | H31: REGULARIZAÇÃO
B35: TOTAL | F35: 0
B36: 2 - DEPÓSITOS NO EXTRATO E NÃO CONTABILIZADOS
B37: DATA | C37: DOCUCMENTO | D37: Nº | E37: JUSTIFICATIVA | F37: VALOR | G37: DATA DO AJUSTE | H37: REGULARIZAÇÃO
B41: TOTAL | F41: 0
B42: 3 - DEPÓSITOS NÃO CONSTANTES NO EXTRATO
B43: DATA | C43: DOCUCMENTO | D43: Nº | E43: JUSTIFICATIVA | F43: VALOR | G43: DATA DO AJUSTE | H43: REGULARIZAÇÃO
B47: TOTAL | F47: 0
B48: 4 - DÉBITOS NO EXTRATO E NÃO CONTABILIZADOS
B49: DATA | C49: DOCUCMENTO | D49: Nº | E49: JUSTIFICATIVA | F49: VALOR | G49: DATA DO AJUSTE | H49: REGULARIZAÇÃO
B53: TOTAL | F53: 0
B64: Anexo III da IN nº 47/2025
B65: Grade de Conciliação Bancária
B66: =B13 -> Referência: 06/2026
B68: CONTA CONTÁBIL: | C68: BANCO: | D68: AGÊNCIA: | E68: CONTA BANCÁRIA: | F68: TÍTULO DA CONTA: | G68: TIPO:
B69: ='29954-5 JUNHO '!B69 -> 111111901/AP0000104 | C69: 1 | D69: 8-6 | E69: =E16 -> 29054-8 | F69: FUNDO ESTADUAL DO TRABALHO - FET | G69: () CONTA CORRENTE | H69: (x) INVESTIMENTOS E APLICAÇÕES FINANCEIRAS
B70: ITEM | C70: HISTORICO | F70: DEBITO | G70: CREDITO | H70: DIFERENÇA
B71: 0 | C71: =C18 -> SALDO DO EXTRATO BANCÁRIO EM 30/06/2026 | F71: 0 | G71: 2844478.1
B72: 1 | C72: DEBITOS NÃO CONSTANTE NO EXTRATO | F72: 0
B73: 2 | C73: DEPÓSITOS CONSTANTES NO EXTRATO E NÃO CONTABILIZADOS | F73: 0
B74: 3 | C74: DEPÓSITOS NÃO CONSTANTES NO EXTRATO | G74: 0
B75: 4 | C75: DÉBITOS NO EXTRATO E NÃO CONTABILIZADOS | G75: 0
...
